<?xml version="1.0" encoding="UTF-8"?>
<!-- Generated by org.testng.reporters.JUnitReportReporter -->
<testsuite hostname="DESKTOP-88R09EB" failures="0" tests="1" name="com.testngconcepts.ExpectedExceptionsDemo" time="0.024" errors="1" timestamp="2023-07-29T22:45:27 IST" skipped="0">
  <testcase classname="com.testngconcepts.ExpectedExceptionsDemo" name="testC" time="0.024">
    <error message="
The exception was thrown with the wrong message: expected &quot;This is null pointer exceptions&quot; but got &quot;This is null pointer exception&quot;" type="org.testng.TestException">
      <![CDATA[org.testng.TestException: 
The exception was thrown with the wrong message: expected "This is null pointer exceptions" but got "This is null pointer exception"
at org.testng.internal.invokers.ExpectedExceptionsHolder.wrongException(ExpectedExceptionsHolder.java:69)
at org.testng.internal.invokers.TestInvoker.considerExceptions(TestInvoker.java:863)
at org.testng.internal.invokers.TestInvoker.invokeMethod(TestInvoker.java:731)
at org.testng.internal.invokers.TestInvoker.invokeTestMethod(TestInvoker.java:221)
at org.testng.internal.invokers.MethodRunner.runInSequence(MethodRunner.java:50)
at org.testng.internal.invokers.TestInvoker$MethodInvocationAgent.invoke(TestInvoker.java:969)
at org.testng.internal.invokers.TestInvoker.invokeTestMethods(TestInvoker.java:194)
at org.testng.internal.invokers.TestMethodWorker.invokeTestMethods(TestMethodWorker.java:148)
at org.testng.internal.invokers.TestMethodWorker.run(TestMethodWorker.java:128)
at java.base/java.util.ArrayList.forEach(ArrayList.java:1511)
at org.testng.TestRunner.privateRun(TestRunner.java:829)
at org.testng.TestRunner.run(TestRunner.java:602)
at org.testng.SuiteRunner.runTest(SuiteRunner.java:437)
at org.testng.SuiteRunner.runSequentially(SuiteRunner.java:431)
at org.testng.SuiteRunner.privateRun(SuiteRunner.java:391)
at org.testng.SuiteRunner.run(SuiteRunner.java:330)
at org.testng.SuiteRunnerWorker.runSuite(SuiteRunnerWorker.java:52)
at org.testng.SuiteRunnerWorker.run(SuiteRunnerWorker.java:95)
at org.testng.TestNG.runSuitesSequentially(TestNG.java:1256)
at org.testng.TestNG.runSuitesLocally(TestNG.java:1176)
at org.testng.TestNG.runSuites(TestNG.java:1099)
at org.testng.TestNG.run(TestNG.java:1067)
at org.testng.remote.AbstractRemoteTestNG.run(AbstractRemoteTestNG.java:115)
at org.testng.remote.RemoteTestNG.initAndRun(RemoteTestNG.java:251)
at org.testng.remote.RemoteTestNG.main(RemoteTestNG.java:77)
Caused by: java.lang.NullPointerException: This is null pointer exception
at com.testngconcepts.ExpectedExceptionsDemo.testC(ExpectedExceptionsDemo.java:19)
at java.base/jdk.internal.reflect.NativeMethodAccessorImpl.invoke0(Native Method)
at java.base/jdk.internal.reflect.NativeMethodAccessorImpl.invoke(NativeMethodAccessorImpl.java:77)
at java.base/jdk.internal.reflect.DelegatingMethodAccessorImpl.invoke(DelegatingMethodAccessorImpl.java:43)
at java.base/java.lang.reflect.Method.invoke(Method.java:568)
at org.testng.internal.invokers.MethodInvocationHelper.invokeMethod(MethodInvocationHelper.java:139)
at org.testng.internal.invokers.TestInvoker.invokeMethod(TestInvoker.java:677)
... 22 more
]]>
    </error>
  </testcase> <!-- testC -->
  <system-out/>
</testsuite> <!-- com.testngconcepts.ExpectedExceptionsDemo -->
